Workbook

Sheet Form Responses 2
A1: Timestamp | B1: Untitled Question

Sheet Sheet30
B1: 19/1/2026 | E1: 25/1/2026 | F1: 27/1/2026 | G1: 28/1/2026
A2: HC SPH | B2: PC
A3: PLAN | B3: 8
A4: -0.25 | B4: 3
A5: -0.5 | B5: 5
A6: -0.75 | B6: 4
A7: -1 | B7: 3
A8: -125 | B8: 6
A9: -1.5 | B9: 4
A10: -1.75 | B10: 6
A11: -2 | B11: 5
A12: -2.25 | B12: 9
A13: -2.5 | B13: 3
A14: -2.75 | B14: 3
A15: -300 | B15: 3
... A21: -10 | B21: 2
A22: -12 | B22: 2 | E22: ```
A23: CYL | B23: 20/1/2026 | D23: 22/1/2026
A24: -0.25/ | B24: 11
A25: 0.50/ | B25: 3 | D25: 2 | E25: 4
A26: -0.75 | B26: 4 | G26: 4
A27: -1 | B27: 7
A28: -1.25 | B28: 4
A29: -1.5 | B29: 4 | D29: 1
A30: -1.75 | B30: 18
A31: -2 | B31: 4
A32: -2.25 | B32: 4
A33: -2.75 | B33: 4
A34: -3 | B34: 3
A35: -5.5 | B35: 1
A36: MINUS/MINUS | B36: 20/1/2026
A37: -0.25/-0.25CYL
A38: -0.25/-0.50CYL
A39: -0.25/-0.75CYL | B39: 1
A40: -0.25/-1.00CYL | B40: 1
A41: -0.25/-1.25CYL
A42: -0.25/-150CYL
A43: -0.25/1.75CYL | B43: 2
A44: -0.25/-2.00CYL | B44: 2
A45: -0.25/-2.25CYL | B45: 2
...

Sheet Sheet32
A2: ARC | B2: 23-1-2026
A3: PLAN
A4: -0.25 | B4: 1
A5: -0.5 | B5: 2
A6: -0.75 | B6: 3
A7: -1 | B7: 3
A8: -125 | B8: 2
A9: -1.5 | B9: 4
A10: -1.75 | B10: 5
A11: -2 | B11: 2
A12: -2.25 | B12: 1
A13: -2.5 | B13: 2
A14: -2.75 | B14: 2
A15: -300 | B15: 3
... A19: -4.25 | B19: 1
A20: -4.5
A21: -4.75 | B21: 2
A22: -5 | B22: 1
A23: -5.25 | B23: 2
A24: -7 | B24: 1
A25: -8 | B25: 1
A26: -10 | B26: 1
A27: -12 | B27: 1
A28: CYL
A29: /-0.25 | B29: 1
A30: /0.50 | B30: 2
A31: /-0.75 | B31: 2
A32: /-1 | B32: 3
A33: -1.25 | B33: 4
A34: -1.5 | B34: 2
A35: -1.75 | B35: 2
A36: -2 | B36: 2
A37: -2.25 | B37: 4
A38: /-2.5 | B38: 2
A39: /-2.75 | B39: 3
A40: /-3 | B40: 3
A41: /-5.5
A42: MINUS/MINUS
A43: -0.25/-0.25CYL
A44: -0.25/-0.50CYL
...

Sheet Sheet33
A2: AO Glasses | B2: 27/1/2026
A3: PLAIN | B3: 1
A4: 1 SPH | B4: 1
A5: -0.5 | B5: 1
A6: -0.75 | B6: 1
A7: -1.25 | B7: 1
A8: -1.75 | B8: 2
A9: -2 | B9: 2
A10: -2.5 | B10: 3
A11: -2.75 | B11: 4
A12: -3 | B12: 6
A13: -3.25 | B13: 2
A14: -3.5 | B14: 3
A15: -3.75 | B15: 4
A16: -4 | B16: 4
... A25: -8 | B25: 4
B26: =SUM(B3:B25) -> 63
A27: CYL
A28: 0/-0.25 | B28: 4
A29: 0/-1.25 | B29: 1
A30: 0/-1.50 | B30: 4
A31: 0/-1.75 | B31: 4
A32: 0/-2.00 | B32: 4
B33: 17
A34: MINUS/MINUS
A35: 0.25/-0.50 | B35: 1
A36: -0.25/-0.25 | B36: 1
A37: -0.25/-0.75 | B37: 2
A38: -0.25/-1.00 | B38: 2
A39: -0.25/-1.25 | B39: 2
A40: -0.25/-1.50 | B40: 2
A41: -0.25/-1.75 | B41: 2
A42: -0.50/-0.25 | B42: 1
A43: -0.50/-0.75 | B43: 2
A44: -.050/-1.00 | B44: 2
A45: -0.50/-1.25 | B45: 1
A46: -0.50/-1.50 | B46: 2
... A119: -4.25/-0.75 | B119: 1
B120: =SUM(B35:B119) -> 164
A121: esiloor/ crizal
...

Sheet Sheet31
A1: GLASS NO | B1: QTY(19/1/2026) | C1: 20/1/2026 | D1: 23/1/2026 | E1: 24/1/2026 | F1: 27/1/2026 | G1: 29/1/2026
A2: SPH CRHC
A3: =0.25 -> 0.25 | B3: 7
A4: 0.5 | B4: 7
A5: 0.75 | B5: 4
A6: 1 | B6: 2 | C6: 4 | D6: 4
A7: 1.25 | B7: 7
A8: 1.5 | B8: 6
A9: 1.75 | B9: 4 | D9: 4
A10: 2 | B10: 4 | F10: 4
A11: 2.25 | B11: 7
A12: 2.5 | B12: 5
A13: 2.75 | B13: 3
A14: 3 | B14: 4
A15: 3.25 | C15: 2 | G15: 2
A16: 3.75 | B16: 2
A17: =5.75 -> 5.75 | B17: 1
A19: CYL | B19: 20/1/2026
A20: 0/+0.25 | B20: 10
A21: 0/+0.50 | B21: 5 | E21: 8
A22: 0/+0.75 | B22: 5
A23: 0/+1.00 | B23: 6
A24: 0./+1.25 | B24: 3
A25: 0/+1.50 | B25: 5 | F25: 4
A26: 0/+1.75 | B26: 14
A27: 0/+2.0 | B27: 5
A28: 0/+2.25 | B28: 17
A29: 0/+2.50 | B29: 3
A30: 0/+2.75 | B30: 6
A31: 0/+3.0 | B31: 3
A32: 0/+3.50 | B32: 4
B33: 4
A34: PLUS/MINUS
A35: 0.25/-0.50 | B35: 2
A36: 0.25/-0.75 | B36: 1
A37: 0.25/-1.00 | B37: 1
A38: 0.25/-1.50 | B38: 2
A39: 0.25/_1.25 | B39: 1
A40: 0.25/-2.50 | B40: 1
A41: 0.5/-1.25 | B41: 1
...

Sheet Sheet13
A1: Code | B1: Brand | C1: Product Margin | D1: Cost Price/ MRP
A2: RB | B2: Rayban | C2: 0.37 | D2: 0.63
A3: CI | B3: Citizen | C3: 0.36 | D3: 0.64
A4: OO | B4: Oakley | C4: 0.41 | D4: 0.59
A5: OX | B5: Oakley | C5: 0.51 | D5: 0.49
A6: RJ | B6: Rayban | C6: 0.37 | D6: 0.63
A7: BE | B7: Burberry | C7: 0.51 | D7: 0.49
A8: PR | B8: Prada | C8: 0.51 | D8: 0.49
A9: PS | B9: Prada | C9: 0.51 | D9: 0.49
A10: DG | B10: Dolce & gabbana | C10: 0.51 | D10: 0.49
A11: VE | B11: Versace | C11: 0.51 | D11: 0.49
A12: VO | B12: Vogue | C12: 0.55 | D12: 0.45
A13: ID | B13: IDEE | C13: 0.55 | D13: 0.45
... A27: TI | B27: Titan Eye+ | C27: 0.37 | D27: 0.63
A28: RE | B28: Renu | C28: 0.25
A29: PL | B29: Polaroid
A30: DJ | B30: David Jones
A31: FC | B31: FCUK
A32: KX | B32: Killer Loop
A33: SQ | B33: Sequinze
A34: TF | B34: Tom Ford
A35: RC | B35: Roberto Cavalli
A36: Bi | B36: Biotrue | C36: 0.24
A37: PG | B37: Page
A38: MJ | B38: Marc Jacobs | C38: 0.52 | D38: 0.48
A39: JC | B39: Jimmy Choo | C39: 0.52 | D39: 0.48
A40: IN | B40: Invu

Sheet Sheet28
A1: DJ15T126_C3_54 | B1: =vlookup(A1,'SECO Stocktake'!$A$2:$CF$1425,83,0) -> 2
A2: DJ15T156_C1_53 | B2: =vlookup(A2,'SECO Stocktake'!$A$2:$CF$1425,83,0) -> #N/A
A3: DJ15T162_C3_52 | B3: =vlookup(A3,'SECO Stocktake'!$A$2:$CF$1425,83,0) -> #N/A
A4: DJ15T163_C5_54 | B4: =vlookup(A4,'SECO Stocktake'!$A$2:$CF$1425,83,0) -> 1
A5: FOS3010PS_003Y2_59 | B5: =vlookup(A5,'SECO Stocktake'!$A$2:$CF$1425,83,0) -> 1
A6: FOS2057S_0039K_52 | B6: =vlookup(A6,'SECO Stocktake'!$A$2:$CF$1425,83,0) -> 1
A7: BOSS HUGO BOSS SHEET | B7: =vlookup(A7,'SECO Stocktake'!$A$2:$CF$1425,83,0) -> 1
A8: VOGUE FANCY SHEET IST | B8: =vlookup(A8,'SECO Stocktake'!$A$2:$CF$1425,83,0) -> #N/A
A9: PUMA | B9: =vlookup(A9,'SECO Stocktake'!$A$2:$CF$1425,83,0) -> #N/A
A10: POLARE | B10: =vlookup(A10,'SECO Stocktake'!$A$2:$CF$1425,83,0) -> #N/A
A11: FT_P089GR3_M | B11: =vlookup(A11,'SECO Stocktake'!$A$2:$CF$1425,83,0) -> #N/A
A12: FT_P089WH4_M | B12: =vlookup(A12,'SECO Stocktake'!$A$2:$CF$1425,83,0) -> 2
... A58: IDS1802_C2_57 | B58: =vlookup(A58,'SECO Stocktake'!$A$2:$CF$1425,83,0) -> 1

Sheet SECO Stocktake
A1: Title | B1: Lens Width | C1: Brands | D1: LOCATION | E1: TYPE | F1: COMMENTS | G1: MRP | DN1: 18-4-26
A2: AO 1.6 CRHMC | C2: AO | E2: SPECTACLE GLASS | G2: 540 | DN2: 256
A3: HC | E3: SPECTACLE GLASS | DN3: 1013
A4: ARC | E4: SPECTACLE GLASS | DN4: 192
A5: PG | E5: SPECTACLE GLASS | DN5: 43
A6: Blue cut PG | E6: SPECTACLE GLASS | DN6: 18
A7: CRKT | E7: SPECTACLE GLASS | DN7: 134
A8: CRKT ARC | E8: SPECTACLE GLASS | DN8: 3
A9: Bluecut CRKT | E9: SPECTACLE GLASS | DN9: 7
A10: Blue ray Progressive | E10: SPECTACLE GLASS | DN10: 0
A11: BLUECUT HMC | E11: SPECTACLE GLASS | DN11: 183
A12: ZEISS BC | DN12: 2
A13: PG 6 LINE | E13: SPECTACLE GLASS | DN13: 108
A14: GLASS | E14: SPECTACLE GLASS | DN14: 79
A15: PGARC | E15: SPECTACLE GLASS | DN15: 2
A16: WHITE KT | E16: SPECTACLE GLASS | DN16: 77
A17: Blue Cut PGKT | DN17: 5
A18: PGKT 6LINE | E18: SPECTACLE GLASS | DN18: 7
A19: PG PROGRESSIVE | DN19: 10
A20: SUPEROL | E20: SPECTACLE GLASS | DN20: 5
A21: CRIZAL UV | E21: SPECTACLE GLASS | DN21: 14
A22: Crizal SV | DN22: 6
A23: Crizal SV KT | DN23: 0
A24: color CLS | DN24: 0
A25: Elements FSV Bluecut | C25: ESSILOR | E25: SPECTACLE GLASS | G25: 600 | DN25: 12
A26: TRIO | C26: ESSILOR | E26: SPECTACLE GLASS | G26: 520 | DN26: 0
A27: KROMOS | E27: SPECTACLE GLASS | DN27: 10
A28: Bandage lens | DN28: 10
A29: LENS SHINE | DN29: 314
A30: CONTACT LENS PCS | E30: CONTACT LENS | DN30: 12
A31: color contact lens | E31: CONTACT LENS | DN31: 3
A32: PROGRESSIVE | E32: SPECTACLE GLASS | DN32: 14
A33: COATED GLASS | E33: SPECTACLE GLASS | DN33: 11
A34: AZEETA SHEET | C34: AZEETA | D34: L6D4-7 | E34: RECTANGLE FULL SHEET FRAME | G34: 900 | DN34: 7
A35: AB1084_C2_53 | B35: 53 | C35: AGNES | D35: T26S2-1 | E35: RECTANGLE SUPRA METAL FRAME | G35: 3480 | DN35: 1
A36: AB1087_C3_53 | B36: 53 | C36: AGNES | D36: T26S2-1 | E36: RECTANGLE FULL METAL FRAME | G36: 3250 | DN36: 1
A37: AB1087_C4_53 | B37: 53 | C37: AGNES | D37: T26S1-1 | E37: RECTANGLE FULL METAL FRAME | G37: 3250 | DN37: 1
A38: AB1090_C1_53 | B38: 53 | C38: AGNES | D38: T75S2-1 | E38: CATEYE SUPRA METAL FRAME | G38: 3725 | DN38: 1
A39: AB1090_C2_53 | B39: 53 | C39: AGNES | D39: T75S3-1 | E39: CATEYE SUPRA METAL FRAME | G39: 3725 | DN39: 1
A40: AB1090_C3_53 | B40: 53 | C40: AGNES | D40: NA | E40: CATEYE SUPRA METAL FRAME | G40: 3725 | DN40: 0
...

Sheet Sheet34

Sheet Sheet29
A1: AR8011 | B1: 502613 | C1: 53
A2: AO 1.6 CRHMC
A3: HC
A4: ARC
A5: PG
A6: Blue cut PG
A7: CRKT
A8: CRKT ARC
A9: Bluecut CRKT
A10: Blue ray Progressive
A11: BLUECUT HMC
A12: ZEISS BC
A13: PG 6 LINE
... A32: AZEETA SHEET
A33: AB1084 | B33: C2 | C33: 53
A34: AB1084 | B34: C4 | C34: 53
A35: AB1087 | B35: C3 | C35: 53
A36: AB1087 | B36: C4 | C36: 53
A37: AB1090 | B37: C1 | C37: 53
A38: AB1090 | B38: C2 | C38: 53
A39: AB1090 | B39: C3 | C39: 53
A40: AB1090 | B40: C4 | C40: 53
A41: AB1094 | B41: C3 | C41: 53
A42: AG1098 | B42: C4 | C42: 49
A43: AB1098 | B43: C5 | C43: 49
A44: AB1098 | B44: C6 | C44: 49
... A147: AB16T150 | B147: C3 | C147: 51
A148: BE4193 | B148: 300213 | C148: 57
A149: BE4201 | B149: 300273 | C149: 58
A150: BE20030 | B150: C01 | C150: M
A151: BIOTRUE SOLUTION 60 ml+SILK LENS SOLUTION
A152: BIOTRUE SOLUTION 120 ml
A153: BIOTRUE 300 ML
A154: RENU | B154: LENSSOLUTION | C154: 120
A155: RENU SOLUTION 300ML
A156: RENU | B156: LENSSOLUTION | C156: 60
A157: BIOFLEX OCCLUSION EYE PATCH (REGULAR)
A158: BRATS & DOLLS
A159: BV2162B | B159: 376 | C159: 53
A160: CKJ751S | B160: 2 | C160: 59
...

Sheet Ray-Ban Working Sheet
A1: SKU | B1: Brands | C1: TYPE | D1: 30/9/22 | E1: 22/4/2023
A2: RB2132_710_58 | B2: RAYBAN | C2: SUNGLASS | D2: 2 | E2: 2
A3: RB2132_71051_55 | B3: RAYBAN | C3: SUNGLASS | D3: 4 | E3: 4
A4: RB2132_90158_55 | B4: RAYBAN | C4: SUNGLASS | D4: 1 | E4: 1
A5: RB2140_955_52 | B5: RAYBAN | C5: SUNGLASS | D5: 1
A6: RB2180_6277B1_49 | B6: RAYBAN | C6: SUNGLASS | D6: 1
A7: RB2448N_710_51 | B7: RAYBAN | C7: SUNGLASS | D7: 1
A8: RB3016_114517_51 | B8: RAYBAN | C8: SUNGLASS | D8: 1
A9: RB3025_00168_58 | B9: RAYBAN | C9: SUNGLASS | D9: 1
A10: RB3016_1160_51 | B10: RAYBAN | C10: SUNGLASS | D10: 1
A11: RB3025_00133_58 | B11: RAYBAN | C11: SUNGLASS | D11: 2
A12: RB3025_0013E_55 | B12: RAYBAN | C12: SUNGLASS | D12: 1
A13: RB3025_0013E_62 | B13: RAYBAN | C13: SUNGLASS | D13: 1
A14: RB3025_0013F_58 | B14: RAYBAN | C14: SUNGLASS | D14: 8
A15: RB3025_00151_55 | B15: RAYBAN | C15: SUNGLASS | D15: 1
A16: RB3025_00151_58 | B16: RAYBAN | C16: SUNGLASS | D16: 10
... A100: RX7129_5577_54 | B100: RAYBAN | C100: FRAME | D100: 1

Sheet FT SECO ALIAS
A1: VO5
A2: FTC046_BK1_M | B2: 1 | C2: =VLOOKUP(A2,$G$2:$H$305,2,0) -> FT_C046BK1_M | G2: FTC046_BK1_M
A3: FTC046_BR3_M | B3: 2 | C3: =VLOOKUP(A3,$G$2:$H$305,2,0) -> FT_C046BR3_M | G3: FTC046_BR3_M
A4: FTC060_BK2_M | B4: 1 | C4: =VLOOKUP(A4,$G$2:$H$305,2,0) -> FT_C060BK2_M | G4: FTC046_PR2_M
A5: FTC066_BR2F_M | B5: 2 | C5: =VLOOKUP(A5,$G$2:$H$305,2,0) -> FT_C066BR2F_M | G5: FTC056_PR2F_M
A6: FTM035_BR6_M | B6: 1 | C6: =VLOOKUP(A6,$G$2:$H$305,2,0) -> FT_M035BR6_M | G6: FTC057_BR1F_M
A7: FTM067_BR4_M | B7: 1 | C7: =VLOOKUP(A7,$G$2:$H$305,2,0) -> FT_M067BR4_M | G7: FTC060_BK2_M
A8: FTM083_BR2F_M | B8: 1 | C8: =VLOOKUP(A8,$G$2:$H$305,2,0) -> FT_M083BR2F_M | G8: FTC062_BR1F_M
A9: FTM101_BR3P_M | B9: 3 | C9: =VLOOKUP(A9,$G$2:$H$305,2,0) -> FT_M101BR3P_M | G9: FTC066_BR2F_M
A10: FTM144_BR2_M | B10: 2 | C10: =VLOOKUP(A10,$G$2:$H$305,2,0) -> FT_M144BR2_M | G10: FTC066_BK3F_M
A11: FTM175_BR1F_M | B11: 1 | C11: =VLOOKUP(A11,$G$2:$H$305,2,0) -> FT_M175BR1F_M | G11: FTC077_BK1_M
A12: FTP161_BR1F_M | B12: 1 | C12: =VLOOKUP(A12,$G$2:$H$305,2,0) -> FT_P161BR1F_M | G12: FTC078_BR2F_M
A13: FTP176_BR1FP_M | B13: 1 | C13: =VLOOKUP(A13,$G$2:$H$305,2,0) -> FT_P176BR1FP_M | G13: FTC078_BR3F_M
... A18: FTP218_BR2FP_M | B18: 1 | C18: =VLOOKUP(A18,$G$2:$H$305,2,0) -> FT_P218BR2FP_M | G18: FTM062_BR3_M
A19: FTP256_PR2F_M | B19: 1 | C19: FTP256_PR2F_M | G19: FTM067_BR4_M
A20: FTP307_BK1FP_M | B20: 2 | C20: =VLOOKUP(A20,$G$2:$H$305,2,0) -> FT_P307BK1FP_M | G20: FTM069_BR1_M
A21: FTP308_BR3F_M | B21: 1 | C21: =VLOOKUP(A21,$G$2:$H$305,2,0) -> FT_P308BR3F_M | G21: FTM083_BR2F_M
A22: FTP337_BR2F_M | B22: 1 | C22: =VLOOKUP(A22,$G$2:$H$305,2,0) -> FT_P337BR2F_M | G22: FTM083_GY1F_M
A23: FTPC001_BR23_M | B23: 1 | C23: =VLOOKUP(A23,$G$2:$H$305,2,0) -> FT_PC001BR23_M | G23: FTM083_PR3F_M
A24: FTPC002_BK5_M | B24: 1 | C24: =VLOOKUP(A24,$G$2:$H$305,2,0) -> FT_PC002BK5_M | G24: FTM101_BR3P_M
A25: FTP220_BR2F_M | B25: 1 | C25: =VLOOKUP(A25,$G$2:$H$305,2,0) -> FT_P220BR2F_M | G25: FTM102_BK2_M
G26: FTM144_BR2_M
G27: FTM148_BU1_M
G28: FTM154_BR2_M
G29: FTM173_BK1_M
G30: FTM173_GR3_M
G31: FTM175_BR1F_M
G32: FTM177_BK3F_M
G33: FTP040_BK1_M
G34: FTP040_BR2_M
G35: FTP089_BK1_M
G36: FTP089_BR2_M
G37: FTP117_BK2_M
... G305: FTR040_BR2_M

Sheet Form Responses 1
B1: Choose Category | C1: Mention SKU Code | D1: Units Moved | E1: MRP | F1: Location on Racks | G1: Date
A2: 43083.639 | B2: Inwarded | C2: RB2132_622_58 | D2: 2 | E2: 6990 | F2: A1 | G2: 43083
A3: 43083.641 | B3: Inwarded | C3: RB2132_622_58 | D3: 1 | E3: 7090 | F3: A1 | G3: 43083
A4: 43083.643 | B4: Inwarded | C4: RB2132_710_58 | D4: 2 | E4: 6990 | F4: A1 | G4: 43083
A5: 43083.646 | B5: Inwarded | C5: RB2140_1187_50 | D5: 1 | E5: 7490 | F5: A1 | G5: 43083
A6: 43083.649 | B6: Inwarded | C6: RB2180_616587_49 | D6: 1 | E6: 7490 | F6: A1 | G6: 43083
A7: 43083.654 | B7: Inwarded | C7: RB3025_00133_58 | D7: 2 | E7: 7690 | F7: A1 | G7: 43083
A8: 43083.672 | B8: Inwarded | C8: RB3025_0013E_58 | D8: 1 | E8: 6490 | F8: A1 | G8: 43083
A9: 43083.678 | B9: Inwarded | C9: RB3025_0013F_58 | D9: 1 | E9: 6490 | F9: A1 | G9: 43083
A10: 43083.681 | B10: Inwarded | C10: RB3025_0013F_58 | D10: 2 | E10: 8190 | F10: A1 | G10: 43083
A11: 43083.687 | B11: Inwarded | C11: RB3025_0014F_58 | D11: 1 | E11: 7490 | F11: A1 | G11: 43083
A12: 43083.688 | B12: Inwarded | C12: RB3025_0013K_58 | D12: 2 | E12: 6490 | F12: A1 | G12: 43083
A13: 43083.696 | B13: Inwarded | C13: RB3025_00151_58 | D13: 3 | E13: 6490 | F13: A1 | G13: 43083
... A63: 43086.706 | B63: Inwarded | C63: RB4194_60171_53 | D63: 1 | E63: 4490 | F63: A5 | G63: 43086
A64: 43086.706 | B64: Inwarded | C64: RB4187_60155_54 | D64: 1 | F64: A5 | G64: 43086
A65: 43086.724 | B65: Inwarded | C65: RB4175_87730_57 | D65: 1 | E65: 8490 | F65: A5 | G65: 43086
A66: 43086.724 | B66: Inwarded | C66: RB4205_6018G_56 | D66: 1 | E66: 4490 | F66: A5 | G66: 43086
A67: 43086.725 | B67: Inwarded | C67: RB4226_618871_56 | D67: 1 | E67: 6990 | G67: 43086
A68: 43086.726 | B68: Inwarded | C68: RB4227_60528G_55 | D68: 1 | E68: 7490 | F68: A5 | G68: 43086
A69: 43086.729 | B69: Inwarded | C69: RB4227_619388_55 | D69: 1 | E69: 7490 | F69: A5 | G69: 43086
A70: 43086.731 | B70: Inwarded | C70: RB4228_618588_58 | D70: 1 | E70: 7990 | F70: A5 | G70: 43086
A71: 43086.732 | B71: Inwarded | C71: RB4251_71013_56 | D71: 1 | E71: 4490 | F71: A5 | G71: 43086
A72: 43087.695 | B72: Inwarded | C72: RB4251_623311_56 | D72: 3 | E72: 4490 | F72: A5 | G72: 43057
A73: 43087.697 | B73: Inwarded | C73: RB4232_619671_57 | D73: 1 | E73: 6490 | F73: A5 | G73: 43057
A74: 43087.699 | B74: Inwarded | C74: RB4251_6018G_56 | D74: 1 | E74: 4490 | F74: A5 | G74: 43057
A75: 43087.701 | B75: Inwarded | C75: RB4211_601S71_56 | D75: 1 | E75: 10490 | F75: A5 | G75: 43057
A76: 43087.72 | B76: Inwarded | C76: RB4251_6019A_56 | D76: 2 | E76: 5290 | F76: A5 | G76: 43087
A77: 43087.721 | B77: Inwarded | C77: RB4251_71071_56 | D77: 2 | E77: 4490 | F77: A6 | G77: 43057
A78: 43087.731 | B78: Inwarded | C78: RB4252_71013_51 | D78: 2 | E78: 5290 | F78: A6 | G78: 43087
A79: 43088.786 | B79: Inwarded | C79: RX6325_2841_53 | D79: 1 | E79: 4290 | F79: A5 | G79: 43088
A80: 43088.787 | B80: Order | C80: RB3471_00113_32 | D80: 1 | F80: A5 | G80: 43058
A81: 43088.788 | B81: Order | C81: RB3025_11217_55 | D81: 1 | F81: A5 | G81: 43088
A82: 43088.789 | B82: Order | C82: RB3025_11217_62 | D82: 1 | F82: A5 | G82: 43088
A83: 43092.64 | B83: Inwarded | C83: RB4252_623419_51 | D83: 3 | E83: 4490 | F83: A6 | G83: 43092
A84: 43092.642 | B84: Inwarded | C84: RB4265_6015J_62 | D84: 1 | E84: 8990 | F84: A6 | G84: 43090
A85: 43092.644 | B85: Inwarded | C85: RB4258_60171_50 | D85: 2 | E85: 6990 | F85: A6 | G85: 43092
A86: 43092.647 | B86: Inwarded | C86: RB4258_71073_50 | D86: 2 | E86: 6990 | F86: A6 | G86: 43092
A87: 43092.652 | B87: Inwarded | C87: RB4273_6019A_52 | D87: 1 | E87: 9690 | F87: A6 | G87: 43092
A88: 43092.655 | B88: Inwarded | C88: RX6049_2502_55 | D88: 6 | E88: 3390 | F88: A6 | G88: 43092
A89: 43092.657 | B89: Inwarded | C89: RX6049_2500_52 | D89: 1 | E89: 4490 | F89: A6 | G89: 43092
...

Sheet Sheet12
A2: SKU | B2: 30/5/19 | C2: MRP | D2: REMARKS | E2: CONDITION | G2: 26/4/2022
A3: LL;. | B3: 1 | E3: CLEANING
A4: BE20030_COL01_60 | B4: 1 | C4: 17090 | D4: CHD RETURN | E4: SCRATCH
A5: BE4193_300213_57 | B5: 1 | C5: 15000 | D5: CHD RETURN | E5: WITHOUT COVER
A6: CK720S_240_57 | B6: 1 | E6: SCRATCH | F6: DISPLAY | G6: 0
A7: DG1231_488_54 | B7: 1 | C7: 14700 | D7: CHD RETURN | E7: WITOUT COVER
A8: DJ_C3 | B8: 1 | D8: DAVID JONES | E8: TEMPLE CODE DAMAGE | F8: BOX-1 | G8: 1
A9: FT_C046BK1_M | B9: 1 | C9: 2099 | E9: SCRATCH SUNGLASS | F9: NA | G9: 1
A10: FT_C060BU1_M | B10: 1 | E10: SCRATCH SUNGLASS | F10: BOX-1 | G10: 1
A11: FT_C065BK1F_M | B11: 1 | E11: SUNGLASS | F11: D4-1 | G11: 1
A12: FT_C067BK1_M | B12: 1 | E12: SUNGLASS | F12: C6R2-1 | G12: 1
A13: FT_C071GR3P_M | E13: Damage | F13: BOX-1 | G13: 1
A14: FT_C072BK2_M | B14: 1 | E14: SCRATCH SUNGLASS
A15: FT_M032BU1_M | E15: SCRATCH | F15: BOX-1 | G15: 1
A16: FT_M035GR5P_M | B16: 1 | E16: SCRATCH SUNGLASS+CODE DAMAGE | F16: BOX-1 | G16: 1
A17: FT_M035GY1_M | B17: 1 | E17: SCRATCH SUNGLASS | F17: BOX-1 | G17: 1
A18: FT_M050BK13P_M | B18: 1 | E18: SCRATCH SUNGLASS | F18: BOX-1 | G18: 1
A19: FT_M062BR3_M | B19: 1 | E19: SCRATCH SUNGLASS
A20: FT_M069BR1_M | B20: 1 | C20: 2699 | E20: SCRATCH SUNGLASS | F20: D4-1 | G20: 1
A21: FT_M083BU5F_M | B21: 1 | E21: SCRATCH SUNGLASS
A22: FT_M101BR3P_M | E22: Glass Damage | F22: C6R2-1
A23: FT_M102BR2_M | B23: 1 | E23: SCRATCH SUNGLASS
A24: FT_M140BU2_M | B24: 1 | C24: 2299 | E24: SCRATCH SUNGLASS | F24: D4-1 | G24: 1
A25: FT_M143BK1_M | B25: 1 | E25: SCRATCH SUNGLASS
A26: FT_M148BU1_M | B26: 1 | C26: 2799 | E26: SCRATCH SUNGLASS | F26: D4-1,BOX-1 | G26: 2
A27: FT_M165BR12_M | B27: 1 | E27: DAMAGE-1 | G27: 1
A28: FT_M171BK1_M | B28: 1 | C28: 2299 | E28: SCRATCH SUNGLASS | F28: D4-1 | G28: 1
A29: FT_M175BR1F_M | B29: 1 | E29: SCRATCH SUNGLASS
A30: FT_M186GR2P_M | B30: 1 | C30: 2099 | E30: SCRATCH SUNGLASS | F30: D4-1 | G30: 1
A31: FT_M187BK1_M | B31: 1 | C31: 1999 | E31: SCRATCH SUNGLASS | F31: D4-1 | G31: 1
A32: FT_N148BU1_M | B32: 1 | E32: SCRATCH SUNGLASS | G32: 1
A33: FT_P150BK3F_M | B33: 2 | D33: CHD RETURN | E33: GLASSES MISSING SUNGLASS-1PCS+SCRATCH-1 PCS | F33: BOX-2 | G33: 2
A34: FT_NBP300GR3_M | B34: 1 | D34: CHD RETURN | E34: BTOKEN FRAME/GLASSES SUNGLASS | G34: 1
A35: FT_NBP357BK5P_55 | B35: 1 | D35: NA | E35: SCRATCH SUNGLASS | G35: 0
A36: FT_P046BK1_M | B36: 1 | C36: DS2 | E36: DAMAGE SUNGLASS | G36: 1
A37: FT_P089GR3_M | B37: 1 | E37: DAMAGE SUNGLASS | F37: DAM-1
A38: FT_P089WH4_M | B38: 2 | E38: SCRATCH SUNGLASS | F38: D3-2 | G38: 2
A39: FT_P220BR2F_M | B39: 1 | E39: SCRATCH SUNGLASS
A40: FT_P222GR1_M | B40: 1 | E40: GLASS MISSING SUNGLASS
A41: FT_P230BK1_M | B41: 1 | E41: SUNGLASS | G41: 1
...

Sheet Dashboard
A1: SKU | B1: MRP | C1: SECO | D1: =VLOOKUP(A1,PIVOT!$A$4:$F$1900,6,0) -> #REF! | E1: CHECK
A2: 1 | B2: 5290 | C2: 0 | D2: 0 | E2: =IF(C2=D2,TRUE) -> TRUE
A3: AG16T150_C2_51 | B3: 1150 | C3: 0 | D3: 0 | E3: =IF(C3=D3,TRUE) -> TRUE
A4: AG4003_MV_51 | B4: 1150 | C4: 0 | D4: 0 | E4: =IF(C4=D4,TRUE) -> TRUE
A5: AG4018-BLK_52 | B5: 1150 | C5: 0 | D5: 0 | E5: =IF(C5=D5,TRUE) -> TRUE
A6: AG6671_C7_54 | B6: 1150 | C6: 1 | D6: =VLOOKUP(A6,PIVOT!$A$4:$F$1900,6,0) -> #REF! | E6: =IF(C6=D6,TRUE) -> #REF!
A7: AR8011_502613_53 | B7: 14820 | C7: 1 | D7: =VLOOKUP(A7,PIVOT!$A$4:$F$1900,6,0) -> #REF! | E7: =IF(C7=D7,TRUE) -> #REF!
A8: AZETA SHEET | B8: 1200 | C8: 13 | D8: =VLOOKUP(A8,PIVOT!$A$4:$F$1900,6,0) -> #REF! | E8: =IF(C8=D8,TRUE) -> #REF!
A9: BABY FRAMES SHEET | B9: 300 | C9: 44 | D9: =VLOOKUP(A9,PIVOT!$A$4:$F$1900,6,0) -> #REF! | E9: =IF(C9=D9,TRUE) -> #REF!
A10: BE3054_11293D_58 | B10: 12710 | C10: 0 | D10: 0 | E10: =IF(C10=D10,TRUE) -> TRUE
A11: BE3071_1005B2_57 | B11: 16500 | C11: 0 | D11: 0 | E11: =IF(C11=D11,TRUE) -> TRUE
A12: BE3072_100313_57 | C12: 0 | D12: 0 | E12: =IF(C12=D12,TRUE) -> TRUE
A13: BE3072_1003B2_57 | B13: 17000 | C13: 0 | D13: 0 | E13: =IF(C13=D13,TRUE) -> TRUE
A14: BE3072_1017B3_57 | B14: 15500 | C14: 0 | D14: 0 | E14: =IF(C14=D14,TRUE) -> TRUE
A15: BE3083_10085W_59 | B15: 11000 | C15: 0 | D15: 0 | E15: =IF(C15=D15,TRUE) -> TRUE
A16: BE4148_300273_55 | B16: 12790 | C16: 0 | D16: 0 | E16: =IF(C16=D16,TRUE) -> TRUE
A17: BE4153Q_34266H_58 | B17: 15000 | C17: 0 | D17: 0 | E17: =IF(C17=D17,TRUE) -> TRUE
A18: BE4170_300187_57 | B18: 14500 | C18: 0 | D18: 0 | E18: =IF(C18=D18,TRUE) -> TRUE
A19: BE4178_300111_58 | B19: 16500 | C19: 0 | D19: 0 | E19: =IF(C19=D19,TRUE) -> TRUE
A20: BE4190_300213_56 | B20: 13000 | C20: 0 | D20: 0 | E20: =IF(C20=D20,TRUE) -> TRUE
A21: BE4192_300213_56 | B21: 13000 | C21: 0 | D21: 0 | E21: =IF(C21=D21,TRUE) -> TRUE
A22: BE4193_300213_56 | B22: 15000 | C22: 0 | D22: 0 | E22: =IF(C22=D22,TRUE) -> TRUE
A23: BE4193_300213_57 | B23: 15000 | C23: 0 | D23: 0 | E23: =IF(C23=D23,TRUE) -> TRUE
A24: BE4194_300187_58 | B24: 10000 | C24: 0 | D24: 0 | E24: =IF(C24=D24,TRUE) -> TRUE
... A28: BE4214_355487_55 | B28: 10500 | C28: 0 | D28: 0 | E28: =IF(C28=D28,TRUE) -> TRUE
A29: BRAND SUPRA | B29: 1000 | C29: 51 | D29: =VLOOKUP(A29,PIVOT!$A$4:$F$1900,6,0) -> #REF! | E29: =IF(C29=D29,TRUE) -> #REF!
A30: BRATS & DOLLS | B30: 1000 | C30: 34 | D30: =VLOOKUP(A30,PIVOT!$A$4:$F$1900,6,0) -> #REF! | E30: =IF(C30=D30,TRUE) -> #REF!
A31: BV2162B_376_53 | B31: 24990 | C31: 0 | D31: 0 | E31: =IF(C31=D31,TRUE) -> TRUE
A32: CARTIER/CREAST | B32: 600 | C32: 2 | D32: =VLOOKUP(A32,PIVOT!$A$4:$F$1900,6,0) -> #REF! | E32: =IF(C32=D32,TRUE) -> #REF!
A33: CK1089S_028_58 | B33: 8750 | C33: 1 | D33: =VLOOKUP(A33,PIVOT!$A$4:$F$1900,6,0) -> #REF! | E33: =IF(C33=D33,TRUE) -> #REF!
A34: CK1145S_975_59 | B34: 8750 | C34: 1 | D34: =VLOOKUP(A34,PIVOT!$A$4:$F$1900,6,0) -> #REF! | E34: =IF(C34=D34,TRUE) -> #REF!
A35: CK1155_030_59 | B35: 8750 | C35: 1 | D35: =VLOOKUP(A35,PIVOT!$A$4:$F$1900,6,0) -> #REF! | E35: =IF(C35=D35,TRUE) -> #REF!
A36: CK1155_272_59 | B36: 8750 | C36: 2 | D36: =VLOOKUP(A36,PIVOT!$A$4:$F$1900,6,0) -> #REF! | E36: =IF(C36=D36,TRUE) -> #REF!
A37: CK1209_003_62 | B37: 9000 | C37: 1 | D37: =VLOOKUP(A37,PIVOT!$A$4:$F$1900,6,0) -> #REF! | E37: =IF(C37=D37,TRUE) -> #REF!
A38: CK1209A_010_62 | B38: 9000 | C38: 1 | D38: =VLOOKUP(A38,PIVOT!$A$4:$F$1900,6,0) -> #REF! | E38: =IF(C38=D38,TRUE) -> #REF!
A39: CK1209A_714_62 | B39: 9000 | C39: 1 | D39: =VLOOKUP(A39,PIVOT!$A$4:$F$1900,6,0) -> #REF! | E39: =IF(C39=D39,TRUE) -> #REF!
A40: CK1209SA_001_62 | B40: 9000 | C40: 1 | D40: =VLOOKUP(A40,PIVOT!$A$4:$F$1900,6,0) -> #REF! | E40: =IF(C40=D40,TRUE) -> #REF!
A41: CK1217S_001_60 | B41: 9000 | C41: 0 | D41: =VLOOKUP(A41,PIVOT!$A$4:$F$1900,6,0) -> #REF! | E41: =IF(C41=D41,TRUE) -> #REF!
A42: CK2145_060_60 | B42: 9000 | C42: 0 | D42: =VLOOKUP(A42,PIVOT!$A$4:$F$1900,6,0) -> #REF! | E42: =IF(C42=D42,TRUE) -> #REF!
A43: CK2146SA_001_59 | B43: 9000 | C43: 1 | D43: =VLOOKUP(A43,PIVOT!$A$4:$F$1900,6,0) -> #REF! | E43: =IF(C43=D43,TRUE) -> #REF!
...

Sheet Brands
A1: Code | B1: Brand
A2: RB | B2: Rayban
A3: CI | B3: Citizen
A4: OO | B4: Oakley
A5: OX | B5: Oakley
A6: RJ | B6: Rayban
A7: BE | B7: Burberry
A8: PR | B8: Prada
A9: PS | B9: Prada
A10: DG | B10: Dolce & gabbana
A11: VE | B11: Versace
A12: VO | B12: Vogue
... A38: IN | B38: Invu

Sheet Sheet11
A1: SKU | B1: 30/5/19 | C1: MRP | D1: DAMAGED PIECES
A2: FT_C072BK2_M | B2: 1
A3: FT_M148BU1_M | B3: 1
A4: FT_M171BK1_M | B4: 1
A5: FT_P230_GR3P_M | B5: 1
A6: FT_P241BK1_M | B6: 1
A7: FT_P322BK1_M | B7: 0 | C7: 1395
A8: FT_PC001BR31P_M | B8: 1
A9: BE20030_COL01_55 | B9: 1
A10: IDS2192_C2_56 | B10: 1 | C10: 2380
A11: IDS2225_C1_53 | B11: 1 | C11: 2250
A12: IDS2472_C1_52 | B12: 1 | C12: 2780
A13: IDS2477_C3_56 | B13: 1 | C13: 2590
A14: IDS2500_C11_58 | B14: 1 | C14: 2350
A15: IDS2500_C41_58 | B15: 1 | C15: 2590
A16: IDS2502_C1P_55 | B16: 1 | C16: 2950
A17: IDS2509_C5_57 | B17: 1 | C17: 2850
A18: OO9263_05_65 | B18: 1 | C18: 7990
A19: OO9350_07_59
A20: RB2140_1188R5_50 | B20: 1 | C20: 7690
A21: RB2140_1188R5_50 | B21: 1 | C21: 7490
A22: RB2140_1188R5_50 | B22: 1 | C22: 7490
A23: RB2140_902_50 | B23: 1 | C23: 7690
A24: RB2180_6277B1_49 | B24: 1
A25: RB3016_90158_51 | B25: 1
A26: RB3025_0145_55 | B26: 1
A27: RB3025_0024J_58 | B27: 1
A28: RB3025_0024W_58 | B28: 1
A29: RB3025_00258_62 | B29: 1 | C29: 7490
A30: RB3025_004_55 | B30: 1 | C30: 5290
A31: RB3025_0045_55 | B31: 1 | C31: 5990
A32: RB3025_11217_55 | B32: 0 | C32: 8690
A33: RB3026_W2027_62 | B33: 0 | C33: 5490
A34: RB3432_004_59 | B34: 1 | C34: 4290
A35: RB3412_002_63 | B35: 0 | C35: 4290
A36: RB3498_00413_61 | B36: 1 | C36: 6290
A37: RJ9506S_22011_50 | B37: 2
A38: TH9711_C4_53 | B38: ?
A39: VO2829SM_W4411_58 | B39: 1 | C39: 2990
A40: VO2855SM_W4411_56 | B40: 1 | C40: 3290

Sheet Detail4-BABY FRAMES SHEET-Order
B1: Choose Category | C1: Mention SKU Code | D1: Units Moved | E1: MRP | F1: Location on Racks | G1: Date
A2: 43199.513 | B2: Order | C2: BABY FRAMES SHEET | D2: -1 | E2: 400 | F2: T | G2: 43197
A3: 43200.442 | B3: Order | C3: BABY FRAMES SHEET | D3: -1 | E3: 300 | F3: T | G3: 43199

Sheet Detail3-BABY FRAMES SHEET-Inwar
B1: Choose Category | C1: Mention SKU Code | D1: Units Moved | E1: MRP | F1: Location on Racks | G1: Date
A2: No contributing data for this category

Sheet Detail2-CK1145SK_975_59-Inwarde
B1: Choose Category | C1: Mention SKU Code | D1: Units Moved | E1: MRP | F1: Location on Racks | G1: Date
A2: 43101.562 | B2: Inwarded | C2: CK1145S_975_59 | D2: 1 | E2: 4590 | F2: D1 | G2: 43101
A3: 43101.565 | B3: Inwarded | C3: CK1145S_975_59 | D3: 1 | E3: 4590 | F3: D1 | G3: 43101

Sheet fk alias
A1: FK SKU | B1: Correct SKU
A2: TH2603_BlkTorC2_60 | B2: TH2603_C2_60
A3: VE4268G_1357 | B3: VE4278B_51368G_57
A4: B4178_331613_58 | B4: B4178_331613_58
A5: BE3054_11293D_58 | B5: BE3054_11293D_58
A6: BE3071_1017B3_57 | B6: BE3071_1017B3_57
A7: BE4148_300273_55 | B7: BE4148_300273_55
A8: BE4153Q_34266H_58 | B8: BE4153Q_34266H_58
A9: BE4190_300213_56 | B9: BE4190_300213_56
A10: BE4201_300187_58 | B10: BE4201_300187_58
A11: DG2075_03413_63 | B11: DG2075_03413_63
A12: DG21013_1362 | B12: DG2119_119013_62
... A2861: VO2924BI_2065_51 | B2861: VO2924BI_2065_51
A2862: FOS2029S_BG4F8_51 | B2862: =VLOOKUP(A2862,Stocktake!$A$14:$C$1942,1,0) -> #REF!
A2863: VE1231_1002_52 | B2863: VE1231_1002_52
A2864: VO4016BI_848_51 | B2864: VO4016BI_848_51
A2865: FT_R046PR3F_M | B2865: =VLOOKUP(A2865,Stocktake!$A$14:$C$1942,1,0) -> #REF!
A2866: TH5221_C4_51 | B2866: =VLOOKUP(A2866,Stocktake!$A$14:$C$1942,1,0) -> #REF!
A2867: VE3206_GB1_54 | B2867: VE3206_GB1_54
A2868: FT_P392BK2_M | B2868: =VLOOKUP(A2868,Stocktake!$A$14:$C$1942,1,0) -> #REF!
A2869: FT_PC001BR31P_M | B2869: =VLOOKUP(A2869,Stocktake!$A$14:$C$1942,1,0) -> #REF!
A2870: VE1210BM_1002_52 | B2870: VE1210BM_1002_52
A2871: FT_R040GR1_M | B2871: =VLOOKUP(A2871,Stocktake!$A$14:$C$1942,1,0) -> #REF!
A2872: FOS2054S_HD18H_52 | B2872: =VLOOKUP(A2872,Stocktake!$A$14:$C$1942,1,0) -> #REF!
A2873: FT_PC001OR32P_M | B2873: =VLOOKUP(A2873,Stocktake!$A$14:$C$1942,1,0) -> #REF!
A2874: VE1238_1002_54 | B2874: VE1238_1002_54
A2875: ID1000_C4_M | B2875: ID1000_C4_52
A2876: FT_R022GR1_M | B2876: =VLOOKUP(A2876,Stocktake!$A$14:$C$1942,1,0) -> #REF!
A2877: VO2787_2406_53 | B2877: VO2787_2406_53
A2878: TH7867_C2_59 | B2878: =VLOOKUP(A2878,Stocktake!$A$14:$C$1942,1,0) -> #REF!
A2879: FT_P380GR2_M | B2879: =VLOOKUP(A2879,Stocktake!$A$14:$C$1942,1,0) -> #REF!
A2880: TH5233_C1_51 | B2880: =VLOOKUP(A2880,Stocktake!$A$14:$C$1942,1,0) -> #REF!
A2881: VO2795S_W65613_53 | B2881: =VLOOKUP(A2881,Stocktake!$A$14:$C$1942,1,0) -> #REF!
A2882: FT_PC001BK30P_M | B2882: =VLOOKUP(A2882,Stocktake!$A$14:$C$1942,1,0) -> #REF!
A2883: EA3025_5017_54 | B2883: =VLOOKUP(A2883,Stocktake!$A$14:$C$1942,1,0) -> #REF!
A2884: VO3991S_35211_58 | B2884: VO3991S_35211_58
A2885: VO2866_2269_53 | B2885: VO2866_2269_53
A2886: CK1089S_028_58 | B2886: =VLOOKUP(A2886,Stocktake!$A$14:$C$1942,1,0) -> #REF!
A2887: VO3845B_548_52 | B2887: VO3845B_548_52
A2888: VO3844_352_52 | B2888: VO3844_352_52
...
